2019-10-12 17:16:52,420 ERROR: Unhandled exception [in ./app/tasks.py:63]
Traceback (most recent call last):
  File "/home/rafael/Documents/meu/microblog/venv/lib/python3.6/site-packages/flask_mail.py", line 492, in send
    message.send(connection)
  File "/home/rafael/Documents/meu/microblog/venv/lib/python3.6/site-packages/flask_mail.py", line 427, in send
    connection.send(self)
  File "/home/rafael/Documents/meu/microblog/venv/lib/python3.6/site-packages/flask_mail.py", line 192, in send
    message.rcpt_options)
  File "/usr/lib/python3.6/smtplib.py", line 852, in sendmail
    self.ehlo_or_helo_if_needed()
  File "/usr/lib/python3.6/smtplib.py", line 600, in ehlo_or_helo_if_needed
    if not (200 <= self.ehlo()[0] <= 299):
  File "/usr/lib/python3.6/smtplib.py", line 440, in ehlo
    self.putcmd(self.ehlo_msg, name or self.local_hostname)
  File "/usr/lib/python3.6/smtplib.py", line 367, in putcmd
    self.send(str)
  File "/usr/lib/python3.6/smtplib.py", line 359, in send
    raise SMTPServerDisconnected('please run connect() first')
smtplib.SMTPServerDisconnected: please run connect() first

During handling of the above exception, another exception occurred:

Traceback (most recent call last):
  File "./app/tasks.py", line 59, in export_posts
    sync=True)
  File "./app/email.py", line 21, in send_email
    mail.send(msg)
  File "/home/rafael/Documents/meu/microblog/venv/lib/python3.6/site-packages/flask_mail.py", line 492, in send
    message.send(connection)
  File "/home/rafael/Documents/meu/microblog/venv/lib/python3.6/site-packages/flask_mail.py", line 152, in __exit__
    self.host.quit()
  File "/usr/lib/python3.6/smtplib.py", line 984, in quit
    res = self.docmd("quit")
  File "/usr/lib/python3.6/smtplib.py", line 420, in docmd
    self.putcmd(cmd, args)
  File "/usr/lib/python3.6/smtplib.py", line 367, in putcmd
    self.send(str)
  File "/usr/lib/python3.6/smtplib.py", line 359, in send
    raise SMTPServerDisconnected('please run connect() first')
smtplib.SMTPServerDisconnected: please run connect() first
2019-10-12 17:18:43,390 INFO: Microblog startup [in ./app/__init__.py:83]
2019-10-12 17:19:38,698 ERROR: Unhandled exception [in ./app/tasks.py:63]
Traceback (most recent call last):
  File "/home/rafael/Documents/meu/microblog/venv/lib/python3.6/site-packages/flask_mail.py", line 492, in send
    message.send(connection)
  File "/home/rafael/Documents/meu/microblog/venv/lib/python3.6/site-packages/flask_mail.py", line 427, in send
    connection.send(self)
  File "/home/rafael/Documents/meu/microblog/venv/lib/python3.6/site-packages/flask_mail.py", line 192, in send
    message.rcpt_options)
  File "/usr/lib/python3.6/smtplib.py", line 852, in sendmail
    self.ehlo_or_helo_if_needed()
  File "/usr/lib/python3.6/smtplib.py", line 600, in ehlo_or_helo_if_needed
    if not (200 <= self.ehlo()[0] <= 299):
  File "/usr/lib/python3.6/smtplib.py", line 440, in ehlo
    self.putcmd(self.ehlo_msg, name or self.local_hostname)
  File "/usr/lib/python3.6/smtplib.py", line 367, in putcmd
    self.send(str)
  File "/usr/lib/python3.6/smtplib.py", line 359, in send
    raise SMTPServerDisconnected('please run connect() first')
smtplib.SMTPServerDisconnected: please run connect() first

During handling of the above exception, another exception occurred:

Traceback (most recent call last):
  File "./app/tasks.py", line 59, in export_posts
    sync=True)
  File "./app/email.py", line 19, in send_email
    mail.send(msg)
  File "/home/rafael/Documents/meu/microblog/venv/lib/python3.6/site-packages/flask_mail.py", line 492, in send
    message.send(connection)
  File "/home/rafael/Documents/meu/microblog/venv/lib/python3.6/site-packages/flask_mail.py", line 152, in __exit__
    self.host.quit()
  File "/usr/lib/python3.6/smtplib.py", line 984, in quit
    res = self.docmd("quit")
  File "/usr/lib/python3.6/smtplib.py", line 420, in docmd
    self.putcmd(cmd, args)
  File "/usr/lib/python3.6/smtplib.py", line 367, in putcmd
    self.send(str)
  File "/usr/lib/python3.6/smtplib.py", line 359, in send
    raise SMTPServerDisconnected('please run connect() first')
smtplib.SMTPServerDisconnected: please run connect() first
2019-10-12 17:25:43,196 INFO: Microblog startup [in ./app/__init__.py:83]
2019-10-12 17:26:38,738 ERROR: Unhandled exception [in ./app/tasks.py:63]
Traceback (most recent call last):
  File "/home/rafael/Documents/meu/microblog/venv/lib/python3.6/site-packages/flask_mail.py", line 492, in send
    message.send(connection)
  File "/home/rafael/Documents/meu/microblog/venv/lib/python3.6/site-packages/flask_mail.py", line 427, in send
    connection.send(self)
  File "/home/rafael/Documents/meu/microblog/venv/lib/python3.6/site-packages/flask_mail.py", line 192, in send
    message.rcpt_options)
  File "/usr/lib/python3.6/smtplib.py", line 852, in sendmail
    self.ehlo_or_helo_if_needed()
  File "/usr/lib/python3.6/smtplib.py", line 600, in ehlo_or_helo_if_needed
    if not (200 <= self.ehlo()[0] <= 299):
  File "/usr/lib/python3.6/smtplib.py", line 440, in ehlo
    self.putcmd(self.ehlo_msg, name or self.local_hostname)
  File "/usr/lib/python3.6/smtplib.py", line 367, in putcmd
    self.send(str)
  File "/usr/lib/python3.6/smtplib.py", line 359, in send
    raise SMTPServerDisconnected('please run connect() first')
smtplib.SMTPServerDisconnected: please run connect() first

During handling of the above exception, another exception occurred:

Traceback (most recent call last):
  File "./app/tasks.py", line 59, in export_posts
    sync=True)
  File "./app/email.py", line 19, in send_email
    mail.send(msg)
  File "/home/rafael/Documents/meu/microblog/venv/lib/python3.6/site-packages/flask_mail.py", line 492, in send
    message.send(connection)
  File "/home/rafael/Documents/meu/microblog/venv/lib/python3.6/site-packages/flask_mail.py", line 152, in __exit__
    self.host.quit()
  File "/usr/lib/python3.6/smtplib.py", line 984, in quit
    res = self.docmd("quit")
  File "/usr/lib/python3.6/smtplib.py", line 420, in docmd
    self.putcmd(cmd, args)
  File "/usr/lib/python3.6/smtplib.py", line 367, in putcmd
    self.send(str)
  File "/usr/lib/python3.6/smtplib.py", line 359, in send
    raise SMTPServerDisconnected('please run connect() first')
smtplib.SMTPServerDisconnected: please run connect() first
2019-10-12 18:33:29,193 INFO: Microblog startup [in ./app/__init__.py:83]
2019-10-12 18:34:24,828 ERROR: Unhandled exception [in ./app/tasks.py:63]
Traceback (most recent call last):
  File "/home/rafael/Documents/meu/microblog/venv/lib/python3.6/site-packages/flask_mail.py", line 492, in send
    message.send(connection)
  File "/home/rafael/Documents/meu/microblog/venv/lib/python3.6/site-packages/flask_mail.py", line 427, in send
    connection.send(self)
  File "/home/rafael/Documents/meu/microblog/venv/lib/python3.6/site-packages/flask_mail.py", line 192, in send
    message.rcpt_options)
  File "/usr/lib/python3.6/smtplib.py", line 852, in sendmail
    self.ehlo_or_helo_if_needed()
  File "/usr/lib/python3.6/smtplib.py", line 600, in ehlo_or_helo_if_needed
    if not (200 <= self.ehlo()[0] <= 299):
  File "/usr/lib/python3.6/smtplib.py", line 440, in ehlo
    self.putcmd(self.ehlo_msg, name or self.local_hostname)
  File "/usr/lib/python3.6/smtplib.py", line 367, in putcmd
    self.send(str)
  File "/usr/lib/python3.6/smtplib.py", line 359, in send
    raise SMTPServerDisconnected('please run connect() first')
smtplib.SMTPServerDisconnected: please run connect() first

During handling of the above exception, another exception occurred:

Traceback (most recent call last):
  File "./app/tasks.py", line 59, in export_posts
    sync=True)
  File "./app/email.py", line 19, in send_email
    mail.send(msg)
  File "/home/rafael/Documents/meu/microblog/venv/lib/python3.6/site-packages/flask_mail.py", line 492, in send
    message.send(connection)
  File "/home/rafael/Documents/meu/microblog/venv/lib/python3.6/site-packages/flask_mail.py", line 152, in __exit__
    self.host.quit()
  File "/usr/lib/python3.6/smtplib.py", line 984, in quit
    res = self.docmd("quit")
  File "/usr/lib/python3.6/smtplib.py", line 420, in docmd
    self.putcmd(cmd, args)
  File "/usr/lib/python3.6/smtplib.py", line 367, in putcmd
    self.send(str)
  File "/usr/lib/python3.6/smtplib.py", line 359, in send
    raise SMTPServerDisconnected('please run connect() first')
smtplib.SMTPServerDisconnected: please run connect() first
2019-10-12 18:35:33,958 INFO: Microblog startup [in /home/rafael/Documents/meu/microblog/app/__init__.py:83]
2019-10-12 18:35:41,598 INFO: Microblog startup [in ./app/__init__.py:83]
