2019-10-13 14:56:17,856 ERROR: Exception on /api/users [GET] [in /home/rafael/Documents/meu/microblog/venv/lib/python3.6/site-packages/flask/app.py:1891]
Traceback (most recent call last):
  File "/home/rafael/Documents/meu/microblog/venv/lib/python3.6/site-packages/flask/app.py", line 2446, in wsgi_app
    response = self.full_dispatch_request()
  File "/home/rafael/Documents/meu/microblog/venv/lib/python3.6/site-packages/flask/app.py", line 1951, in full_dispatch_request
    rv = self.handle_user_exception(e)
  File "/home/rafael/Documents/meu/microblog/venv/lib/python3.6/site-packages/flask/app.py", line 1820, in handle_user_exception
    reraise(exc_type, exc_value, tb)
  File "/home/rafael/Documents/meu/microblog/venv/lib/python3.6/site-packages/flask/_compat.py", line 39, in reraise
    raise value
  File "/home/rafael/Documents/meu/microblog/venv/lib/python3.6/site-packages/flask/app.py", line 1949, in full_dispatch_request
    rv = self.dispatch_request()
  File "/home/rafael/Documents/meu/microblog/venv/lib/python3.6/site-packages/flask/app.py", line 1935, in dispatch_request
    return self.view_functions[rule.endpoint](**req.view_args)
  File "/home/rafael/Documents/meu/microblog/app/api/users.py", line 11, in get_users
    page = request.args.get('page', 1, type=int)
NameError: name 'request' is not defined
2019-10-16 13:30:50,324 INFO: Microblog startup [in ./app/__init__.py:85]
2019-10-16 13:30:50,775 INFO: Microblog startup [in ./app/__init__.py:85]
2019-10-16 13:32:48,054 INFO: Microblog startup [in ./app/__init__.py:85]
2019-10-16 13:34:18,896 INFO: Microblog startup [in ./app/__init__.py:85]
2019-10-16 13:35:08,119 INFO: Microblog startup [in ./app/__init__.py:85]
